2025-03-19 09:39:19,616 - ERROR - Error handling fields: ['11', '18', '8', '672387462', 'MES', 'FUT', '20250321', '0.0', '', '5', 'CME', 'USD', 'MESH5', 'MES', '0000e1a7.67d9cc6b.01.01', '20250318 15:59:46 US/Central', 'DUD052704', 'CME', 'SLD', '1', '5618.00', '818291297', '1', '0', '1', '5618.00', '', '', '', '', '1']
Traceback (most recent call last):
  File "C:\Users\Aaron\AppData\Local\Programs\Python\Python313\Lib\zoneinfo\_common.py", line 12, in load_tzdata
    return resources.files(package_name).joinpath(resource_name).open("rb")
           ~~~~~~~~~~~~~~~^^^^^^^^^^^^^^
  File "C:\Users\Aaron\AppData\Local\Programs\Python\Python313\Lib\importlib\resources\_common.py", line 46, in wrapper
    return func(anchor)
  File "C:\Users\Aaron\AppData\Local\Programs\Python\Python313\Lib\importlib\resources\_common.py", line 56, in files
    return from_package(resolve(anchor))
                        ~~~~~~~^^^^^^^^
  File "C:\Users\Aaron\AppData\Local\Programs\Python\Python313\Lib\functools.py", line 934, in wrapper
    return dispatch(args[0].__class__)(*args, **kw)
           ~~~~~~~~~~~~~~~~~~~~~~~~~~~^^^^^^^^^^^^^
  File "C:\Users\Aaron\AppData\Local\Programs\Python\Python313\Lib\importlib\resources\_common.py", line 82, in _
    return importlib.import_module(cand)
           ~~~~~~~~~~~~~~~~~~~~~~~^^^^^^
  File "C:\Users\Aaron\AppData\Local\Programs\Python\Python313\Lib\importlib\__init__.py", line 88, in import_module
    return _bootstrap._gcd_import(name[level:], package, level)
           ~~~~~~~~~~~~~~~~~~~~~~^^^^^^^^^^^^^^^^^^^^^^^^^^^^^^
  File "<frozen importlib._bootstrap>", line 1387, in _gcd_import
  File "<frozen importlib._bootstrap>", line 1360, in _find_and_load
  File "<frozen importlib._bootstrap>", line 1310, in _find_and_load_unlocked
  File "<frozen importlib._bootstrap>", line 488, in _call_with_frames_removed
  File "<frozen importlib._bootstrap>", line 1387, in _gcd_import
  File "<frozen importlib._bootstrap>", line 1360, in _find_and_load
  File "<frozen importlib._bootstrap>", line 1310, in _find_and_load_unlocked
  File "<frozen importlib._bootstrap>", line 488, in _call_with_frames_removed
  File "<frozen importlib._bootstrap>", line 1387, in _gcd_import
  File "<frozen importlib._bootstrap>", line 1360, in _find_and_load
  File "<frozen importlib._bootstrap>", line 1324, in _find_and_load_unlocked
ModuleNotFoundError: No module named 'tzdata'

During handling of the above exception, another exception occurred:

Traceback (most recent call last):
  File "c:\Users\Aaron\ACCN\venv\Lib\site-packages\ib_insync\decoder.py", line 198, in interpret
    handler(fields)
    ~~~~~~~^^^^^^^^
  File "c:\Users\Aaron\ACCN\venv\Lib\site-packages\ib_insync\decoder.py", line 447, in execDetails
    time = cast(datetime, parseIBDatetime(timeStr))
                          ~~~~~~~~~~~~~~~^^^^^^^^^
  File "c:\Users\Aaron\ACCN\venv\Lib\site-packages\ib_insync\util.py", line 543, in parseIBDatetime
    t = t.replace(tzinfo=ZoneInfo(s2))
                         ~~~~~~~~^^^^
  File "C:\Users\Aaron\AppData\Local\Programs\Python\Python313\Lib\zoneinfo\_common.py", line 24, in load_tzdata
    raise ZoneInfoNotFoundError(f"No time zone found with key {key}")
zoneinfo._common.ZoneInfoNotFoundError: 'No time zone found with key US/Central'
2025-03-19 09:39:19,653 - ERROR - Error handling fields: ['11', '18', '16', '672387462', 'MES', 'FUT', '20250321', '0.0', '', '5', 'CME', 'USD', 'MESH5', 'MES', '0000e1a7.67d9eaa8.01.01', '20250318 17:00:00 US/Central', 'DUD052704', 'CME', 'BOT', '1', '5619.00', '818291301', '1', '0', '1', '5619.00', '', '', '', '', '1']
Traceback (most recent call last):
  File "C:\Users\Aaron\AppData\Local\Programs\Python\Python313\Lib\zoneinfo\_common.py", line 12, in load_tzdata
    return resources.files(package_name).joinpath(resource_name).open("rb")
           ~~~~~~~~~~~~~~~^^^^^^^^^^^^^^
  File "C:\Users\Aaron\AppData\Local\Programs\Python\Python313\Lib\importlib\resources\_common.py", line 46, in wrapper
    return func(anchor)
  File "C:\Users\Aaron\AppData\Local\Programs\Python\Python313\Lib\importlib\resources\_common.py", line 56, in files
    return from_package(resolve(anchor))
                        ~~~~~~~^^^^^^^^
  File "C:\Users\Aaron\AppData\Local\Programs\Python\Python313\Lib\functools.py", line 934, in wrapper
    return dispatch(args[0].__class__)(*args, **kw)
           ~~~~~~~~~~~~~~~~~~~~~~~~~~~^^^^^^^^^^^^^
  File "C:\Users\Aaron\AppData\Local\Programs\Python\Python313\Lib\importlib\resources\_common.py", line 82, in _
    return importlib.import_module(cand)
           ~~~~~~~~~~~~~~~~~~~~~~~^^^^^^
  File "C:\Users\Aaron\AppData\Local\Programs\Python\Python313\Lib\importlib\__init__.py", line 88, in import_module
    return _bootstrap._gcd_import(name[level:], package, level)
           ~~~~~~~~~~~~~~~~~~~~~~^^^^^^^^^^^^^^^^^^^^^^^^^^^^^^
  File "<frozen importlib._bootstrap>", line 1387, in _gcd_import
  File "<frozen importlib._bootstrap>", line 1360, in _find_and_load
  File "<frozen importlib._bootstrap>", line 1310, in _find_and_load_unlocked
  File "<frozen importlib._bootstrap>", line 488, in _call_with_frames_removed
  File "<frozen importlib._bootstrap>", line 1387, in _gcd_import
  File "<frozen importlib._bootstrap>", line 1360, in _find_and_load
  File "<frozen importlib._bootstrap>", line 1310, in _find_and_load_unlocked
  File "<frozen importlib._bootstrap>", line 488, in _call_with_frames_removed
  File "<frozen importlib._bootstrap>", line 1387, in _gcd_import
  File "<frozen importlib._bootstrap>", line 1360, in _find_and_load
  File "<frozen importlib._bootstrap>", line 1324, in _find_and_load_unlocked
ModuleNotFoundError: No module named 'tzdata'

During handling of the above exception, another exception occurred:

Traceback (most recent call last):
  File "c:\Users\Aaron\ACCN\venv\Lib\site-packages\ib_insync\decoder.py", line 198, in interpret
    handler(fields)
    ~~~~~~~^^^^^^^^
  File "c:\Users\Aaron\ACCN\venv\Lib\site-packages\ib_insync\decoder.py", line 447, in execDetails
    time = cast(datetime, parseIBDatetime(timeStr))
                          ~~~~~~~~~~~~~~~^^^^^^^^^
  File "c:\Users\Aaron\ACCN\venv\Lib\site-packages\ib_insync\util.py", line 543, in parseIBDatetime
    t = t.replace(tzinfo=ZoneInfo(s2))
                         ~~~~~~~~^^^^
  File "C:\Users\Aaron\AppData\Local\Programs\Python\Python313\Lib\zoneinfo\_common.py", line 24, in load_tzdata
    raise ZoneInfoNotFoundError(f"No time zone found with key {key}")
zoneinfo._common.ZoneInfoNotFoundError: 'No time zone found with key US/Central'
2025-03-19 09:39:19,655 - INFO - Synchronization complete
2025-03-19 09:39:21,748 - INFO - Shard ID None has connected to Gateway (Session ID: 263909a7b39bb74b16a83987340db2c0).
2025-03-19 09:39:31,901 - INFO - Executing buy order for ES1 at 2025-03-19T09:39:26.769727
2025-03-19 09:39:37,537 - INFO - updatePortfolio: PortfolioItem(contract=Future(conId=672387462, symbol='MES', lastTradeDateOrContractMonth='20250321', right='0', multiplier='5', primaryExchange='CME', currency='USD', localSymbol='MESH5', tradingClass='MES'), position=0.0, marketPrice=5613.0, marketValue=0.0, averageCost=0.0, unrealizedPNL=0.0, realizedPNL=-6.24, account='DUD052704')
2025-03-19 09:39:47,230 - INFO - Placing buy order for MES at 2025-03-19T09:39:26.769727
2025-03-19 09:39:48,861 - INFO - placeOrder: New order Trade(contract=Contract(secType='FUT', conId=672387462, symbol='MES', lastTradeDateOrContractMonth='20250321', multiplier='5', exchange='CME', currency='USD', localSymbol='MESH5', tradingClass='MES'), order=MarketOrder(orderId=20, clientId=1, action='BUY', totalQuantity=1), orderStatus=OrderStatus(orderId=20, status='PendingSubmit', filled=0.0, remaining=0.0, avgFillPrice=0.0, permId=0, parentId=0, lastFillPrice=0.0, clientId=0, whyHeld='', mktCapPrice=0.0), fills=[], log=[TradeLogEntry(time=datetime.datetime(2025, 3, 18, 22, 39, 48, 861277, tzinfo=datetime.timezone.utc), status='PendingSubmit', message='', errorCode=0)], advancedError='')
2025-03-19 09:40:19,491 - INFO - Email confirmation sent successfully.
2025-03-19 09:40:23,743 - INFO - Order placed: Trade(contract=Contract(secType='FUT', conId=672387462, symbol='MES', lastTradeDateOrContractMonth='20250321', multiplier='5', exchange='CME', currency='USD', localSymbol='MESH5', tradingClass='MES'), order=MarketOrder(orderId=20, clientId=1, action='BUY', totalQuantity=1), orderStatus=OrderStatus(orderId=20, status='PendingSubmit', filled=0.0, remaining=0.0, avgFillPrice=0.0, permId=0, parentId=0, lastFillPrice=0.0, clientId=0, whyHeld='', mktCapPrice=0.0), fills=[], log=[TradeLogEntry(time=datetime.datetime(2025, 3, 18, 22, 39, 48, 861277, tzinfo=datetime.timezone.utc), status='PendingSubmit', message='', errorCode=0)], advancedError='')
